<?xml version="1.0" ?>
<!-- =================================================================================== -->
<!-- |    This document was autogenerated by xacro from allegro_hand_description_right.xacro | -->
<!-- |    EDITING THIS FILE BY HAND IS NOT RECOMMENDED                                 | -->
<!-- =================================================================================== -->
<robot name="allegro_hand_right" xmlns:xacro="http://www.ros.org/wiki/xacro">
    <!-- ======================== BASE PARAMS ========================= -->
    <!-- ======================== FINGER PARAMS ======================== -->
    <!-- full height from joint to tip. when used,
    the radius of the finger tip sphere will be subtracted
    and one fixed link will be added for the tip. -->
    <!-- ========================= THUMB PARAMS ========================= -->
    <!-- ========================= LIMITS ========================= -->
    <!-- ============================================================================= -->
    <!-- PALM -->
    <link name="world" />
    <joint name="global" type="fixed">
        <parent link="world" />
        <child link="palm_link" />
        <!--<origin xyz="0 0 0.095" rpy="0 0 0"/>-->
        <origin xyz="0 0 0.0" rpy="0 0 0" />
    </joint>
    <link name="palm_link">
        <visual>
            <geometry>
                <mesh filename="package://allegro_hand_description/meshes/g0.stl" scale="0.001 0.001 0.001" />
            </geometry>
            <origin rpy="0 3.14 1.57" xyz="0.104 -0.091 -0.1" />
            <material name="black">
                <color rgba="0.2 0.2 0.2 1" />
            </material>
        </visual>
        <collision>
            <geometry>
                <mesh filename="package://allegro_hand_description/meshes/g0.stl" scale="0.001 0.001 0.001" />
            </geometry>
            <origin rpy="0 3.14 1.57" xyz="0.104 -0.091 -0.1" />
        </collision>
        <inertial>
            <origin rpy="0 0 0" xyz="0 0 0.0475" />
            <mass value="0.4154" />
            <inertia ixx="1e-4" ixy="0.0" ixz="0.0" iyy="1e-4" iyz="0.0" izz="1e-4" />
        </inertial>
    </link>
    <!-- ============================================================================= -->
    <!-- FINGERS -->
    <!-- RIGHT HAND due to which finger is number 0 -->
    <!-- for LEFT HAND switch the sign of the **offset_origin_y** and **finger_angle_r** parameters-->
    <!-- [LINK 0, 4, 8] -->
    <link name="link_0_0">
        <visual>
            <geometry>
                <mesh filename="package://allegro_hand_description/meshes/l1.stl" scale="0.001 0.001 0.001" />
            </geometry>
            <origin rpy="0 0 -1.57" xyz="-0.025 -0.021 0.165" />
            <material name="black">
                <color rgba="0.2 0.2 0.2 1" />
            </material>
        </visual>
        <collision>
            <geometry>
                <mesh filename="package://allegro_hand_description/meshes/l1.stl" scale="0.001 0.001 0.001" />
            </geometry>
            <origin rpy="0 0 -1.57" xyz="-0.025 -0.021 0.165" />
        </collision>
        <inertial>
            <mass value="0.0119" />
            <origin rpy="0 0 0" xyz="0 0 0" />
            <inertia ixx="1.01666658333e-06" ixy="0.0" ixz="0.0" iyy="6.47677333333e-07" iyz="0.0" izz="1.01666658333e-06" />
        </inertial>
    </link>
    <joint name="joint_0_0" type="revolute">
        <axis xyz="0 0 1" />
        <limit effort="15" lower="-0.47" upper="0.47" velocity="7" />
        <parent link="palm_link" />
        <child link="link_0_0" />
        <origin rpy="-0.08726646255 0 0" xyz="0.0025 0.036 -0.00945" />
        <dynamics damping="3" friction="10" />
    </joint>
    <!-- [LINK 1, 5, 9] -->
    <link name="link_1_0">
        <visual>
            <geometry>
                <mesh filename="package://allegro_hand_description/meshes/l2.stl" scale="0.001 0.001 0.001" />
            </geometry>
            <origin rpy="0 0 -1.57" xyz="-0.025 -0.021 0.145" />
            <material name="black" />
        </visual>
        <collision>
            <geometry>
                <mesh filename="package://allegro_hand_description/meshes/l2.stl" scale="0.001 0.001 0.001" />
            </geometry>
            <origin rpy="0 0 -1.57" xyz="-0.025 -0.021 0.145" />
        </collision>
        <inertial>
            <mass value="0.065" />
            <origin rpy="0 0 0" xyz="0 0 0" />
            <inertia ixx="7.95654166667e-05" ixy="1.7199e-05" ixz="8.75875e-06" iyy="2.47088833333e-05" iyz="2.413125e-05" izz="7.95654166667e-05" />
        </inertial>
    </link>
    <joint name="joint_1_0" type="revolute">
        <limit effort="15" lower="-0.196" upper="1.61" velocity="7" />
        <axis xyz="0 1 0" />
        <parent link="link_0_0" />
        <child link="link_1_0" />
        <origin xyz="0 0 0.021" />
        <dynamics damping="3" friction="5" />
    </joint>
    <!-- [LINK 2, 6, 10]-->
    <link name="link_2_0">
        <visual>
            <geometry>
                <mesh filename="package://allegro_hand_description/meshes/l3.stl" scale="0.001 0.001 0.001" />
            </geometry>
            <origin rpy="0 0 -1.57" xyz="-0.025 -0.021 0.0945" />
            <material name="black" />
        </visual>
        <collision>
            <geometry>
                <mesh filename="package://allegro_hand_description/meshes/l3.stl" scale="0.001 0.001 0.001" />
            </geometry>
            <origin rpy="0 0 -1.57" xyz="-0.025 -0.021 0.0945" />
        </collision>
        <inertial>
            <mass value="0.0355" />
            <origin rpy="0 0 0" xyz="0 0 0" />
            <inertia ixx="2.63979183333e-05" ixy="6.67968e-06" ixz="4.783625e-06" iyy="1.34948516667e-05" iyz="9.372e-06" izz="2.63979183333e-05" />
        </inertial>
    </link>
    <joint name="joint_2_0" type="revolute">
        <axis xyz="0 1 0" />
        <limit effort="15" lower="-0.174" upper="1.709" velocity="7" />
        <parent link="link_1_0" />
        <child link="link_2_0" />
        <origin xyz="0 0 0.051" />
        <dynamics damping="8" friction="10" />
    </joint>
    <!-- [LINK 3, 7, 11] -->
    <link name="link_3_0">
        <visual>
            <geometry>
                <mesh filename="package://allegro_hand_description/meshes/l4.stl" scale="0.001 0.001 0.001" />
            </geometry>
            <origin rpy="0 0 -1.57" xyz="-0.025 -0.021 0.0561" />
            <material name="black" />
        </visual>
        <collision>
            <geometry>
                <mesh filename="package://allegro_hand_description/meshes/l4.stl" scale="0.001 0.001 0.001" />
            </geometry>
            <origin rpy="0 0 -1.57" xyz="-0.025 -0.021 0.0561" />
        </collision>
        <inertial>
            <mass value="0.0096" />
            <origin rpy="0 0 0" xyz="0 0 0" />
            <inertia ixx="4.701248e-06" ixy="1.255968e-06" ixz="1.2936e-06" iyy="3.649312e-06" iyz="1.7622e-06" izz="4.701248e-06" />
        </inertial>
    </link>
    <joint name="joint_3_0" type="revolute">
        <axis xyz="0 1 0" />
        <limit effort="15" lower="-0.227" upper="1.618" velocity="7" />
        <parent link="link_2_0" />
        <child link="link_3_0" />
        <origin xyz="0 0 0.0384" />
        <dynamics damping="10" friction="12" />
    </joint>
    <!-- [FINGER TIP] -->
    <link name="link_3_0_tip">
        <visual>
            <geometry>
                <mesh filename="package://allegro_hand_description/meshes/l5.stl" scale="0.001 0.001 0.001" />
            </geometry>
            <origin rpy="0 0 -1.57" xyz="-0.001 -0.0015 -0.00767" />
            <material name="white">
                <color rgba=".9 .9 .9 1" />
            </material>
        </visual>
        <collision>
            <geometry>
                <mesh filename="package://allegro_hand_description/meshes/l5.stl" scale="0.001 0.001 0.001" />
            </geometry>
            <origin rpy="0 0 -1.57" xyz="-0.001 -0.0015 -0.00767" />
        </collision>
        <inertial>
            <mass value="0.0168" />
            <origin rpy="0 0 0" xyz="0 0 0" />
            <inertia ixx="9.68e-07" ixy="0" ixz="0" iyy="9.68e-07" iyz="0" izz="9.68e-07" />
        </inertial>
    </link>
    <joint name="joint_3_0_tip" type="fixed">
        <parent link="link_3_0" />
        <child link="link_3_0_tip" />
        <origin rpy="0 0 0" xyz="0 0 0.0267" />
    </joint>
    <!-- [LINK 0, 4, 8] -->
    <link name="link_4_0">
        <visual>
            <geometry>
                <mesh filename="package://allegro_hand_description/meshes/l1.stl" scale="0.001 0.001 0.001" />
            </geometry>
            <origin rpy="0 0 -1.57" xyz="-0.025 -0.021 0.165" />
            <material name="black" />
        </visual>
        <collision>
            <geometry>
                <mesh filename="package://allegro_hand_description/meshes/l1.stl" scale="0.001 0.001 0.001" />
            </geometry>
            <origin rpy="0 0 -1.57" xyz="-0.025 -0.021 0.165" />
        </collision>
        <inertial>
            <mass value="0.0119" />
            <origin rpy="0 0 0" xyz="0 0 0" />
            <inertia ixx="1.01666658333e-06" ixy="0.0" ixz="0.0" iyy="6.47677333333e-07" iyz="0.0" izz="1.01666658333e-06" />
        </inertial>
    </link>
    <joint name="joint_4_0" type="revolute">
        <axis xyz="0 0 1" />
        <limit effort="15" lower="-0.47" upper="0.47" velocity="7" />
        <parent link="palm_link" />
        <child link="link_4_0" />
        <origin rpy="0.0 0 0" xyz="0 0 -0.0079" />
        <dynamics damping="3" friction="10" />
    </joint>
    <!-- [LINK 1, 5, 9] -->
    <link name="link_5_0">
        <visual>
            <geometry>
                <mesh filename="package://allegro_hand_description/meshes/l2.stl" scale="0.001 0.001 0.001" />
            </geometry>
            <origin rpy="0 0 -1.57" xyz="-0.025 -0.021 0.145" />
            <material name="black" />
        </visual>
        <collision>
            <geometry>
                <mesh filename="package://allegro_hand_description/meshes/l2.stl" scale="0.001 0.001 0.001" />
            </geometry>
            <origin rpy="0 0 -1.57" xyz="-0.025 -0.021 0.145" />
        </collision>
        <inertial>
            <mass value="0.065" />
            <origin rpy="0 0 0" xyz="0 0 0" />
            <inertia ixx="7.95654166667e-05" ixy="1.7199e-05" ixz="8.75875e-06" iyy="2.47088833333e-05" iyz="2.413125e-05" izz="7.95654166667e-05" />
        </inertial>
    </link>
    <joint name="joint_5_0" type="revolute">
        <limit effort="15" lower="-0.196" upper="1.61" velocity="7" />
        <axis xyz="0 1 0" />
        <parent link="link_4_0" />
        <child link="link_5_0" />
        <origin xyz="0 0 0.021" />
        <dynamics damping="3" friction="5" />
    </joint>
    <!-- [LINK 2, 6, 10]-->
    <link name="link_6_0">
        <visual>
            <geometry>
                <mesh filename="package://allegro_hand_description/meshes/l3.stl" scale="0.001 0.001 0.001" />
            </geometry>
            <origin rpy="0 0 -1.57" xyz="-0.025 -0.021 0.0945" />
            <material name="black" />
        </visual>
        <collision>
            <geometry>
                <mesh filename="package://allegro_hand_description/meshes/l3.stl" scale="0.001 0.001 0.001" />
            </geometry>
            <origin rpy="0 0 -1.57" xyz="-0.025 -0.021 0.0945" />
        </collision>
        <inertial>
            <mass value="0.0355" />
            <origin rpy="0 0 0" xyz="0 0 0" />
            <inertia ixx="2.63979183333e-05" ixy="6.67968e-06" ixz="4.783625e-06" iyy="1.34948516667e-05" iyz="9.372e-06" izz="2.63979183333e-05" />
        </inertial>
    </link>
    <joint name="joint_6_0" type="revolute">
        <axis xyz="0 1 0" />
        <limit effort="15" lower="-0.174" upper="1.709" velocity="7" />
        <parent link="link_5_0" />
        <child link="link_6_0" />
        <origin xyz="0 0 0.051" />
        <dynamics damping="8" friction="10" />
    </joint>
    <!-- [LINK 3, 7, 11] -->
    <link name="link_7_0">
        <visual>
            <geometry>
                <mesh filename="package://allegro_hand_description/meshes/l4.stl" scale="0.001 0.001 0.001" />
            </geometry>
            <origin rpy="0 0 -1.57" xyz="-0.025 -0.021 0.0561" />
            <material name="black" />
        </visual>
        <collision>
            <geometry>
                <mesh filename="package://allegro_hand_description/meshes/l4.stl" scale="0.001 0.001 0.001" />
            </geometry>
            <origin rpy="0 0 -1.57" xyz="-0.025 -0.021 0.0561" />
        </collision>
        <inertial>
            <mass value="0.0096" />
            <origin rpy="0 0 0" xyz="0 0 0" />
            <inertia ixx="4.701248e-06" ixy="1.255968e-06" ixz="1.2936e-06" iyy="3.649312e-06" iyz="1.7622e-06" izz="4.701248e-06" />
        </inertial>
    </link>
    <joint name="joint_7_0" type="revolute">
        <axis xyz="0 1 0" />
        <limit effort="15" lower="-0.227" upper="1.618" velocity="7" />
        <parent link="link_6_0" />
        <child link="link_7_0" />
        <origin xyz="0 0 0.0384" />
        <dynamics damping="10" friction="12" />
    </joint>
    <!-- [FINGER TIP] -->
    <link name="link_7_0_tip">
        <visual>
            <geometry>
                <mesh filename="package://allegro_hand_description/meshes/l5.stl" scale="0.001 0.001 0.001" />
            </geometry>
            <origin rpy="0 0 -1.57" xyz="-0.001 -0.0015 -0.00767" />
            <material name="white">
                <color rgba=".9 .9 .9 1" />
            </material>
        </visual>
        <collision>
            <geometry>
                <mesh filename="package://allegro_hand_description/meshes/l5.stl" scale="0.001 0.001 0.001" />
            </geometry>
            <origin rpy="0 0 -1.57" xyz="-0.001 -0.0015 -0.00767" />
        </collision>
        <inertial>
            <mass value="0.0168" />
            <origin rpy="0 0 0" xyz="0 0 0" />
            <inertia ixx="9.68e-07" ixy="0" ixz="0" iyy="9.68e-07" iyz="0" izz="9.68e-07" />
        </inertial>
    </link>
    <joint name="joint_7_0_tip" type="fixed">
        <parent link="link_7_0" />
        <child link="link_7_0_tip" />
        <origin rpy="0 0 0" xyz="0 0 0.0267" />
    </joint>
    <!-- [LINK 0, 4, 8] -->
    <link name="link_8_0">
        <visual>
            <geometry>
                <mesh filename="package://allegro_hand_description/meshes/l1.stl" scale="0.001 0.001 0.001" />
            </geometry>
            <origin rpy="0 0 -1.57" xyz="-0.025 -0.021 0.165" />
            <material name="black">
                <color rgba="0.2 0.2 0.2 1" />
            </material>
        </visual>
        <collision>
            <geometry>
                <mesh filename="package://allegro_hand_description/meshes/l1.stl" scale="0.001 0.001 0.001" />
            </geometry>
            <origin rpy="0 0 -1.57" xyz="-0.025 -0.021 0.165" />
        </collision>
        <inertial>
            <mass value="0.0119" />
            <origin rpy="0 0 0" xyz="0 0 0" />
            <inertia ixx="1.01666658333e-06" ixy="0.0" ixz="0.0" iyy="6.47677333333e-07" iyz="0.0" izz="1.01666658333e-06" />
        </inertial>
    </link>
    <joint name="joint_8_0" type="revolute">
        <axis xyz="0 0 1" />
        <limit effort="15" lower="-0.47" upper="0.47" velocity="7" />
        <parent link="palm_link" />
        <child link="link_8_0" />
        <origin rpy="0.08726646255 0 0" xyz="0.0025 -0.036 -0.00945" />
        <dynamics damping="3" friction="10" />
    </joint>
    <!-- [LINK 1, 5, 9] -->
    <link name="link_9_0">
        <visual>
            <geometry>
                <mesh filename="package://allegro_hand_description/meshes/l2.stl" scale="0.001 0.001 0.001" />
            </geometry>
            <origin rpy="0 0 -1.57" xyz="-0.025 -0.021 0.145" />
            <material name="black" />
        </visual>
        <collision>
            <geometry>
                <mesh filename="package://allegro_hand_description/meshes/l2.stl" scale="0.001 0.001 0.001" />
            </geometry>
            <origin rpy="0 0 -1.57" xyz="-0.025 -0.021 0.145" />
        </collision>
        <inertial>
            <mass value="0.065" />
            <origin rpy="0 0 0" xyz="0 0 0" />
            <inertia ixx="7.95654166667e-05" ixy="1.7199e-05" ixz="8.75875e-06" iyy="2.47088833333e-05" iyz="2.413125e-05" izz="7.95654166667e-05" />
        </inertial>
    </link>
    <joint name="joint_9_0" type="revolute">
        <limit effort="15" lower="-0.196" upper="1.61" velocity="7" />
        <axis xyz="0 1 0" />
        <parent link="link_8_0" />
        <child link="link_9_0" />
        <origin xyz="0 0 0.021" />
        <dynamics damping="3" friction="5" />
    </joint>
    <!-- [LINK 2, 6, 10]-->
    <link name="link_10_0">
        <visual>
            <geometry>
                <mesh filename="package://allegro_hand_description/meshes/l3.stl" scale="0.001 0.001 0.001" />
            </geometry>
            <origin rpy="0 0 -1.57" xyz="-0.025 -0.021 0.0945" />
            <material name="black" />
        </visual>
        <collision>
            <geometry>
                <mesh filename="package://allegro_hand_description/meshes/l3.stl" scale="0.001 0.001 0.001" />
            </geometry>
            <origin rpy="0 0 -1.57" xyz="-0.025 -0.021 0.0945" />
        </collision>
        <inertial>
            <mass value="0.0355" />
            <origin rpy="0 0 0" xyz="0 0 0" />
            <inertia ixx="2.63979183333e-05" ixy="6.67968e-06" ixz="4.783625e-06" iyy="1.34948516667e-05" iyz="9.372e-06" izz="2.63979183333e-05" />
        </inertial>
    </link>
    <joint name="joint_10_0" type="revolute">
        <axis xyz="0 1 0" />
        <limit effort="15" lower="-0.174" upper="1.709" velocity="7" />
        <parent link="link_9_0" />
        <child link="link_10_0" />
        <origin xyz="0 0 0.051" />
        <dynamics damping="8" friction="10" />
    </joint>
    <!-- [LINK 3, 7, 11] -->
    <link name="link_11_0">
        <visual>
            <geometry>
                <mesh filename="package://allegro_hand_description/meshes/l4.stl" scale="0.001 0.001 0.001" />
            </geometry>
            <origin rpy="0 0 -1.57" xyz="-0.025 -0.021 0.0561" />
            <material name="black" />
        </visual>
        <collision>
            <geometry>
                <mesh filename="package://allegro_hand_description/meshes/l4.stl" scale="0.001 0.001 0.001" />
            </geometry>
            <origin rpy="0 0 -1.57" xyz="-0.025 -0.021 0.0561" />
        </collision>
        <inertial>
            <mass value="0.0096" />
            <origin rpy="0 0 0" xyz="0 0 0" />
            <inertia ixx="4.701248e-06" ixy="1.255968e-06" ixz="1.2936e-06" iyy="3.649312e-06" iyz="1.7622e-06" izz="4.701248e-06" />
        </inertial>
    </link>
    <joint name="joint_11_0" type="revolute">
        <axis xyz="0 1 0" />
        <limit effort="15" lower="-0.227" upper="1.618" velocity="7" />
        <parent link="link_10_0" />
        <child link="link_11_0" />
        <origin xyz="0 0 0.0384" />
        <dynamics damping="10" friction="12" />
    </joint>
    <!-- [FINGER TIP] -->
    <link name="link_11_0_tip">
        <visual>
            <geometry>
                <mesh filename="package://allegro_hand_description/meshes/l5.stl" scale="0.001 0.001 0.001" />
            </geometry>
            <origin rpy="0 0 -1.57" xyz="-0.001 -0.0015 -0.00767" />
            <material name="white">
                <color rgba=".9 .9 .9 1" />
            </material>
        </visual>
        <collision>
            <geometry>
                <mesh filename="package://allegro_hand_description/meshes/l5.stl" scale="0.001 0.001 0.001" />
            </geometry>
            <origin rpy="0 0 -1.57" xyz="-0.001 -0.0015 -0.00767" />
        </collision>
        <inertial>
            <mass value="0.0168" />
            <origin rpy="0 0 0" xyz="0 0 0" />
            <inertia ixx="9.68e-07" ixy="0" ixz="0" iyy="9.68e-07" iyz="0" izz="9.68e-07" />
        </inertial>
    </link>
    <joint name="joint_11_0_tip" type="fixed">
        <parent link="link_11_0" />
        <child link="link_11_0_tip" />
        <origin rpy="0 0 0" xyz="0 0 0.0267" />
    </joint>
    <!-- THUMB -->
    <!-- [LINK 12] -->
    <link name="link_12_0">
        <visual>
            <geometry>
                <mesh filename="package://allegro_hand_description/meshes/t1.stl" scale="0.001 0.001 0.001" />
            </geometry>
            <origin rpy="0.0174532951 3.14 0" xyz="-0.0215 -0.0277 -0.011" />
            <material name="black">
                <color rgba=".2 .2 .2 1" />
            </material>
        </visual>
        <collision>
            <geometry>
                <mesh filename="package://allegro_hand_description/meshes/t1.stl" scale="0.001 0.001 0.001" />
            </geometry>
            <origin rpy="0.0174532951 3.14 0" xyz="-0.0215 -0.0277 -0.011" />
        </collision>
        <inertial>
            <mass value="0.0176" />
            <origin rpy="0 0 0" xyz="0 0 0" />
            <inertia ixx="1.89273333333e-5" ixy="7.16716e-06" ixz="5.35568e-06" iyy="1.43008213333e-05" iyz="6.8068e-06" izz="1.89273333333e-05" />
        </inertial>
    </link>
    <joint name="joint_12_0" type="revolute">
        <axis xyz="-1 0 0" />
        <limit effort="15" lower="0.263" upper="1.396" velocity="7" />
        <parent link="palm_link" />
        <child link="link_12_0" />
        <origin rpy="0 -1.65806278845 -1.5707963259" xyz="0.0015 0.014 -0.06747" />
        <dynamics damping="3" friction="10" />
    </joint>
    <!-- [LINK 13] -->
    <link name="link_13_0">
        <visual>
            <geometry>
                <mesh filename="package://allegro_hand_description/meshes/t2.stl" scale="0.001 0.001 0.001" />
            </geometry>
            <origin rpy="3.14 0 3.14" xyz="-0.0225 -0.03 -0.05" />
            <material name="black">
                <color rgba=".2 .2 .2 1" />
            </material>
        </visual>
        <collision>
            <geometry>
                <mesh filename="package://allegro_hand_description/meshes/t2.stl" scale="0.001 0.001 0.001" />
            </geometry>
            <origin rpy="3.14 0 3.14" xyz="-0.0225 -0.03 -0.05" />
        </collision>
        <inertial>
            <mass value="0.0119" />
            <origin rpy="0 0 0" xyz="0 0 0" />
            <inertia ixx="4.24250866667e-06" ixy="1.032087e-06" ixz="1.603525e-06" iyy="4.52362633333e-06" iyz="1.44808125e-06" izz="4.24250866667e-06" />
        </inertial>
    </link>
    <joint name="joint_13_0" type="revolute">
        <axis xyz="0 0 1" />
        <limit effort="15" lower="-0.105" upper="1.163" velocity="7" />
        <parent link="link_12_0" />
        <child link="link_13_0" />
        <origin xyz="0.0005 0.0035 0.0399" />
        <dynamics damping="3" friction="5" />
    </joint>
    <!-- [LINK 14] -->
    <link name="link_14_0">
        <visual>
            <geometry>
                <mesh filename="package://allegro_hand_description/meshes/t3.stl" scale="0.001 0.001 0.001" />
            </geometry>
            <origin rpy="3.14 0 3.14" xyz="-0.0225 -0.03 -0.077" />
            <material name="black" />
        </visual>
        <collision>
            <geometry>
                <mesh filename="package://allegro_hand_description/meshes/t3.stl" scale="0.001 0.001 0.001" />
            </geometry>
            <origin rpy="3.14 0 3.14" xyz="-0.0225 -0.03 -0.077" />
        </collision>
        <inertial>
            <mass value="0.038" />
            <origin rpy="0 0 0" xyz="0 0 0" />
            <inertia ixx="4.30439933333e-05" ixy="9.57068e-06" ixz="5.1205e-06" iyy="1.44451933333e-05" iyz="1.342825e-05" izz="4.30439933333e-05" />
        </inertial>
    </link>
    <joint name="joint_14_0" type="revolute">
        <axis xyz="0 1 0" />
        <limit effort="15" lower="-0.189" upper="1.644" velocity="7" />
        <parent link="link_13_0" />
        <child link="link_14_0" />
        <origin xyz="0 0 0.027" />
        <dynamics damping="3" friction="10" />
    </joint>
    <!-- [LINK 15] -->
    <link name="link_15_0">
        <visual>
            <geometry>
                <mesh filename="package://allegro_hand_description/meshes/t4.stl" scale="0.001 0.001 0.001" />
            </geometry>
            <origin rpy="3.14 0 3.14" xyz="-0.0225 -0.03 -0.115" />
            <material name="black" />
        </visual>
        <collision>
            <geometry>
                <mesh filename="package://allegro_hand_description/meshes/t4.stl" scale="0.001 0.001 0.001" />
            </geometry>
            <origin rpy="3.14 0 3.14" xyz="-0.0225 -0.03 -0.115" />
        </collision>
        <inertial>
            <mass value="0.0388" />
            <origin rpy="0 0 0" xyz="0 0 0" />
            <inertia ixx="3.29223173333e-05" ixy="8.042076e-06" ixz="5.2283e-06" iyy="1.47493026667e-5" iyz="1.1283525e-5" izz="3.29223173333e-05" />
        </inertial>
    </link>
    <joint name="joint_15_0" type="revolute">
        <axis xyz="0 1 0" />
        <limit effort="15" lower="-0.162" upper="1.719" velocity="7" />
        <parent link="link_14_0" />
        <child link="link_15_0" />
        <origin xyz="0 0 0.038" />
        <dynamics damping="3" friction="12" />
    </joint>
    <!-- [FINGER TIP] -->
    <link name="link_15_0_tip">
        <visual>
            <geometry>
                <mesh filename="package://allegro_hand_description/meshes/t5.stl" scale="0.001 0.001 0.001" />
            </geometry>
            <origin rpy="3.14 0 3.14" xyz="-0.0225 -0.03 -0.1575" />
            <material name="white">
                <color rgba=".9 .9 .9 1" />
            </material>
        </visual>
        <collision>
            <geometry>
                <mesh filename="package://allegro_hand_description/meshes/t5.stl" scale="0.001 0.001 0.001" />
            </geometry>
            <origin rpy="3.14 0 3.14" xyz="-0.0225 -0.03 -0.1575" />
        </collision>
        <inertial>
            <mass value="0.0168" />
            <origin rpy="0 0 0" xyz="0 0 0" />
            <inertia ixx="9.68e-07" ixy="0" ixz="0" iyy="9.68e-07" iyz="0" izz="9.68e-07" />
        </inertial>
    </link>
    <joint name="joint_15_0_tip" type="fixed">
        <parent link="link_15_0" />
        <child link="link_15_0_tip" />
        <origin rpy="0 0 0" xyz="0 0 0.0423" />
    </joint>
    <!-- ============================================================================= -->
    <!-- THUMB MACRO -->
    <!-- END THUMB MACRO -->
    <!-- THREE FINGER MACRO -->
    <!-- [[END]] THREE FINGER MACRO -->
    <transmission name="trans_joint_0_0">
        <type>transmission_interface/SimpleTransmission</type>
        <joint name="joint_0_0">
            <hardwareInterface>hardware_interface/EffortJointInterface</hardwareInterface>
        </joint>
        <actuator name="joint_0_0_motor">
            <hardwareInterface>hardware_interface/EffortJointInterface</hardwareInterface>
            <mechanicalReduction>1</mechanicalReduction>
        </actuator>
    </transmission>
    <transmission name="trans_joint_1_0">
        <type>transmission_interface/SimpleTransmission</type>
        <joint name="joint_1_0">
            <hardwareInterface>hardware_interface/EffortJointInterface</hardwareInterface>
        </joint>
        <actuator name="joint_1_0_motor">
            <hardwareInterface>hardware_interface/EffortJointInterface</hardwareInterface>
            <mechanicalReduction>1</mechanicalReduction>
        </actuator>
    </transmission>
    <transmission name="trans_joint_2_0">
        <type>transmission_interface/SimpleTransmission</type>
        <joint name="joint_2_0">
            <hardwareInterface>hardware_interface/EffortJointInterface</hardwareInterface>
        </joint>
        <actuator name="joint_2_0_motor">
            <hardwareInterface>hardware_interface/EffortJointInterface</hardwareInterface>
            <mechanicalReduction>1</mechanicalReduction>
        </actuator>
    </transmission>
    <transmission name="trans_joint_3_0">
        <type>transmission_interface/SimpleTransmission</type>
        <joint name="joint_3_0">
            <hardwareInterface>hardware_interface/EffortJointInterface</hardwareInterface>
        </joint>
        <actuator name="joint_3_0_motor">
            <hardwareInterface>hardware_interface/EffortJointInterface</hardwareInterface>
            <mechanicalReduction>1</mechanicalReduction>
        </actuator>
    </transmission>
    <transmission name="trans_joint_4_0">
        <type>transmission_interface/SimpleTransmission</type>
        <joint name="joint_4_0">
            <hardwareInterface>hardware_interface/EffortJointInterface</hardwareInterface>
        </joint>
        <actuator name="joint_4_0_motor">
            <hardwareInterface>hardware_interface/EffortJointInterface</hardwareInterface>
            <mechanicalReduction>1</mechanicalReduction>
        </actuator>
    </transmission>
    <transmission name="trans_joint_5_0">
        <type>transmission_interface/SimpleTransmission</type>
        <joint name="joint_5_0">
            <hardwareInterface>hardware_interface/EffortJointInterface</hardwareInterface>
        </joint>
        <actuator name="joint_5_0_motor">
            <hardwareInterface>hardware_interface/EffortJointInterface</hardwareInterface>
            <mechanicalReduction>1</mechanicalReduction>
        </actuator>
    </transmission>
    <transmission name="trans_joint_6_0">
        <type>transmission_interface/SimpleTransmission</type>
        <joint name="joint_6_0">
            <hardwareInterface>hardware_interface/EffortJointInterface</hardwareInterface>
        </joint>
        <actuator name="joint_6_0_motor">
            <hardwareInterface>hardware_interface/EffortJointInterface</hardwareInterface>
            <mechanicalReduction>1</mechanicalReduction>
        </actuator>
    </transmission>
    <transmission name="trans_joint_7_0">
        <type>transmission_interface/SimpleTransmission</type>
        <joint name="joint_7_0">
            <hardwareInterface>hardware_interface/EffortJointInterface</hardwareInterface>
        </joint>
        <actuator name="joint_7_0_motor">
            <hardwareInterface>hardware_interface/EffortJointInterface</hardwareInterface>
            <mechanicalReduction>1</mechanicalReduction>
        </actuator>
    </transmission>
    <transmission name="trans_joint_8_0">
        <type>transmission_interface/SimpleTransmission</type>
        <joint name="joint_8_0">
            <hardwareInterface>hardware_interface/EffortJointInterface</hardwareInterface>
        </joint>
        <actuator name="joint_8_0_motor">
            <hardwareInterface>hardware_interface/EffortJointInterface</hardwareInterface>
            <mechanicalReduction>1</mechanicalReduction>
        </actuator>
    </transmission>
    <transmission name="trans_joint_9_0">
        <type>transmission_interface/SimpleTransmission</type>
        <joint name="joint_9_0">
            <hardwareInterface>hardware_interface/EffortJointInterface</hardwareInterface>
        </joint>
        <actuator name="joint_9_0_motor">
            <hardwareInterface>hardware_interface/EffortJointInterface</hardwareInterface>
            <mechanicalReduction>1</mechanicalReduction>
        </actuator>
    </transmission>
    <transmission name="trans_joint_10_0">
        <type>transmission_interface/SimpleTransmission</type>
        <joint name="joint_10_0">
            <hardwareInterface>hardware_interface/EffortJointInterface</hardwareInterface>
        </joint>
        <actuator name="joint_10_0_motor">
            <hardwareInterface>hardware_interface/EffortJointInterface</hardwareInterface>
            <mechanicalReduction>1</mechanicalReduction>
        </actuator>
    </transmission>
    <transmission name="trans_joint_11_0">
        <type>transmission_interface/SimpleTransmission</type>
        <joint name="joint_11_0">
            <hardwareInterface>hardware_interface/EffortJointInterface</hardwareInterface>
        </joint>
        <actuator name="joint_11_0_motor">
            <hardwareInterface>hardware_interface/EffortJointInterface</hardwareInterface>
            <mechanicalReduction>1</mechanicalReduction>
        </actuator>
    </transmission>
    <transmission name="trans_joint_12_0">
        <type>transmission_interface/SimpleTransmission</type>
        <joint name="joint_12_0">
            <hardwareInterface>hardware_interface/EffortJointInterface</hardwareInterface>
        </joint>
        <actuator name="joint_12_0_motor">
            <hardwareInterface>hardware_interface/EffortJointInterface</hardwareInterface>
            <mechanicalReduction>1</mechanicalReduction>
        </actuator>
    </transmission>
    <transmission name="trans_joint_13_0">
        <type>transmission_interface/SimpleTransmission</type>
        <joint name="joint_13_0">
            <hardwareInterface>hardware_interface/EffortJointInterface</hardwareInterface>
        </joint>
        <actuator name="joint_13_0_motor">
            <hardwareInterface>hardware_interface/EffortJointInterface</hardwareInterface>
            <mechanicalReduction>1</mechanicalReduction>
        </actuator>
    </transmission>
    <transmission name="trans_joint_14_0">
        <type>transmission_interface/SimpleTransmission</type>
        <joint name="joint_14_0">
            <hardwareInterface>hardware_interface/EffortJointInterface</hardwareInterface>
        </joint>
        <actuator name="joint_14_0_motor">
            <hardwareInterface>hardware_interface/EffortJointInterface</hardwareInterface>
            <mechanicalReduction>1</mechanicalReduction>
        </actuator>
    </transmission>
    <transmission name="trans_joint_15_0">
        <type>transmission_interface/SimpleTransmission</type>
        <joint name="joint_15_0">
            <hardwareInterface>hardware_interface/EffortJointInterface</hardwareInterface>
        </joint>
        <actuator name="joint_15_0_motor">
            <hardwareInterface>hardware_interface/EffortJointInterface</hardwareInterface>
            <mechanicalReduction>1</mechanicalReduction>
        </actuator>
    </transmission>
    <gazebo>
        <plugin name="gazebo_ros_control">
            <robotNamespace>/</robotNamespace>
        </plugin>
    </gazebo>
</robot>

